Traceback (most recent call last):
  File "/scratch/roko/sequence-polishing/yhes.py", line 145, in <module>
    main()
  File "/scratch/roko/sequence-polishing/yhes.py", line 141, in main
    trainer.fit(model, datamodule=data)
  File "/scratch/miniconda3/envs/roko/lib/python3.9/site-packages/pytorch_lightning/trainer/trainer.py", line 552, in fit
    self._run(model)
  File "/scratch/miniconda3/envs/roko/lib/python3.9/site-packages/pytorch_lightning/trainer/trainer.py", line 855, in _run
    self.data_connector.prepare_data(model)
  File "/scratch/miniconda3/envs/roko/lib/python3.9/site-packages/pytorch_lightning/trainer/connectors/data_connector.py", line 74, in prepare_data
    self.trainer.datamodule.prepare_data()
  File "/scratch/miniconda3/envs/roko/lib/python3.9/site-packages/pytorch_lightning/core/datamodule.py", line 428, in wrapped_fn
    fn(*args, **kwargs)
  File "/scratch/roko/sequence-polishing/THEDataModule.py", line 31, in prepare_data
    assert(os.path.exists(self.val_path))
AssertionError